Workbook

Sheet A. Organizational Information
A1: CLIENT NAME: | C1: Nagaworld Limited | E1: Item | F1: Percentage | G1: Bally
A2: YEAR END: | C2: =_xlfn.CONCAT("FOR THE FINANCIAL YEAR ENDED ",TEXT(C4,"dd-MMM-yyyy")) -> FOR THE FINANCIAL YEAR ENDED 31-Dec-2025 | D2: All Received | E2: =COUNTIF($D$8:$D$13,D2) -> 0 | F2: =E2/SUM($E$2:$E$5) -> 0 | G2: Opera
C3: 45658 | D3: Partially Received | E3: =COUNTIF($D$8:$D$13,D3) -> 0 | F3: =E3/SUM($E$2:$E$5) -> 0 | G3: Simphony POS | H3: Not Applicable
C4: 46022 | D4: Not Received | E4: =COUNTIF($D$8:$D$13,D4) -> 6 | F4: =E4/SUM($E$2:$E$5) -> 1 | G4: Material Control | H4: Not Received
D5: Not Applicable | E5: =COUNTIF($D$8:$D$13,D5) -> 0 | F5: =E5/SUM($E$2:$E$5) -> 0 | H5: Partially Received
A6: List of Items Requested / Inquired | H6: All Received
A7: Area | B7: File Ref | C7: Document / Evidence Requested | D7: Status | E7: Client's Remarks | F7: BDO Remarks
A8: Information Security | B8: A1 | C8: Policies & Procedures which include the following, but not limited to: • User Access Management • Password Management • User Access Rights Review and Monitoring • Privileged Access Management • Program Change Management • Program Development Management (System Development Life Cycle) • Batch Jobs Monitoring • Backup & Restoration Management • Incident / Problem Management | D8: Not Received
B9: A2 | C9: IT Organization Chart | D9: Not Received
B10: A3 | C10: Finance Organization Chart | D10: Not Received
B11: A4 | C11: Network diagrams / architectures | D11: Not Received
B12: A5 | C12: =_xlfn.CONCAT("HR Listing for all resigned employess as of ",TEXT(C4,"dd-MMM-yyyy")) -> HR Listing for all resigned employess as of 31-Dec-2025 | D12: Not Received
B13: A6 | C13: =_xlfn.CONCAT("HR Listing for all active employees as of ",TEXT(C4,"dd-MMM-yyyy")) -> HR Listing for all active employees as of 31-Dec-2025 | D13: Not Received

Sheet B. Access to Program & Data
A1: CLIENT NAME: | C1: ='A. Organizational Information'!C1 -> Nagaworld Limited | N1: Item | O1: Percentage
A2: YEAR END: | C2: ='A. Organizational Information'!C2 -> FOR THE FINANCIAL YEAR ENDED 31-Dec-2025 | M2: All Received | N2: =COUNTIF($E$9:$H$72,M2) -> 0 | O2: =N2/SUM($N$2:$N$5) -> 0 | Q2: Not Applicable
M3: Partially Received | N3: =COUNTIF($E$9:$H$72,M3) -> 0 | O3: =N3/SUM($N$2:$N$5) -> 0 | Q3: Not Received
M4: Not Received | N4: =COUNTIF($E$9:$L$72,M4) -> 400 | O4: =N4/SUM($N$2:$N$5) -> 1 | Q4: Partially Received
M5: Not Applicable | N5: =COUNTIF($E$9:$H$72,M5) -> 0 | O5: =N5/SUM($N$2:$N$5) -> 0 | Q5: All Received
A7: List of Items Requested / Inquired | E7: Status | M7: Client's Remarks | N7: BDO Remarks
A8: Area | B8: File Ref | C8: Document / Evidence Requested | D8: Layers | E8: ='A. Organizational Information'!G1 -> Bally | F8: ='A. Organizational Information'!G2 -> Opera | G8: ='A. Organizational Information'!G3 -> Simphony POS | H8: ='A. Organizational Information'!G4 -> Material Control | I8: Sun Accounting | J8: HRMS | K8: K2 | L8: VR
A9: User Access Administration (Creation, Deletion/Deactivation and Modifcation) | B9: B1 | C9: ="System generated list of users with creation / deletion or deactivation / modification date for all in-scope systems from "&TEXT('A. Organizational Information'!C3,"dd-MMM-yyyy")&" to "&TEXT('A. Organizational Information'!C4,"dd-MMM-yyyy")&"" -> System generated list of users with creation / deletion or deactivation / modification date for all in-scope systems from 01-Jan-2025 to 31-Dec-2025 | D9: Application (APP) | E9: Not Received | F9: Not Received | G9: Not Received | H9: Not Received | I9: Not Received | J9: Not Received | K9: Not Received | L9: Not Received
A10: Note: For DB / OS / AD layers, we are only inspecting on super users (users with privileged access) | C10: Relevant data elements (RDE) within listing should include but not limited to the following: - User ID - User name - User Creation date - User Modification date - User Disable/Deletion/Deactivation date 'Note: If system generated list is not available, to consider below options if applicable Option A - Ticketing system list of user access creation / deletion or deactivation / modification' | D10: Database (DB) | E10: Not Received | F10: Not Received | G10: Not Received | H10: Not Received | I10: Not Received | J10: Not Received | K10: Not Received | L10: Not Received
D11: Operating System (OS) | E11: Not Received | F11: Not Received | G11: Not Received | H11: Not Received | I11: Not Received | J11: Not Received | K11: Not Received | L11: Not Received
D12: Windows Active Directory (AD) | E12: Not Received
B13: B1a | C13: System screenshots of extraction step of the user listing extracted for B1. Please ensure the below are included in the screenshot: 1) Timestamp 2) Total number of row counts (to match with the total number of users shown in the user listing) | D13: Application (APP) | E13: Not Received | F13: Not Received | G13: Not Received | H13: Not Received | I13: Not Received | J13: Not Received | K13: Not Received | L13: Not Received
D14: Database (DB) | E14: Not Received | F14: Not Received | G14: Not Received | H14: Not Received | I14: Not Received | J14: Not Received | K14: Not Received | L14: Not Received
D15: Operating System (OS) | E15: Not Received | F15: Not Received | G15: Not Received | H15: Not Received | I15: Not Received | J15: Not Received | K15: Not Received | L15: Not Received
D16: Windows Active Directory (AD) | E16: Not Received
B17: B2 | C17: Evidences of samples of user access creation request samples The evidence shall include the following but not limited to: - Approvals obtained prior to access creation - Access requested by user - Access granted upon creation Note: Sample will only be selected when B1 is received. | D17: Application (APP) | E17: Not Received | F17: Not Received | G17: Not Received | H17: Not Received | I17: Not Received | J17: Not Received | K17: Not Received | L17: Not Received
D18: Database (DB) | E18: Not Received | F18: Not Received | G18: Not Received | H18: Not Received | I18: Not Received | J18: Not Received | K18: Not Received | L18: Not Received
D19: Operating System (OS) | E19: Not Received | F19: Not Received | G19: Not Received | H19: Not Received | I19: Not Received | J19: Not Received | K19: Not Received | L19: Not Received
D20: Windows Active Directory (AD) | E20: Not Received
B21: B3 | C21: Evidences of samples of user access modification request samples The evidence shall include the following but not limited to: - Approvals obtained prior to access modification - Access requested by user - Access granted upon modification Note: Sample will only be selected when B1 is received. | D21: Application (APP) | E21: Not Received | F21: Not Received | G21: Not Received | H21: Not Received | I21: Not Received | J21: Not Received | K21: Not Received | L21: Not Received
D22: Database (DB) | E22: Not Received | F22: Not Received | G22: Not Received | H22: Not Received | I22: Not Received | J22: Not Received | K22: Not Received | L22: Not Received
D23: Operating System (OS) | E23: Not Received | F23: Not Received | G23: Not Received | H23: Not Received | I23: Not Received | J23: Not Received | K23: Not Received | L23: Not Received
D24: Windows Active Directory (AD) | E24: Not Received
B25: B4 | C25: Evidences of samples of user access disablement/deletion/deactivation request samples The evidence shall include the following but not limited to: - Approvals obtained prior to access disablement/deletion/deactivation (if any) - User termination / resignation date Note: Sample will only be selected when B1 is received. | D25: Application (APP) | E25: Not Received | F25: Not Received | G25: Not Received | H25: Not Received | I25: Not Received | J25: Not Received | K25: Not Received | L25: Not Received
D26: Database (DB) | E26: Not Received | F26: Not Received | G26: Not Received | H26: Not Received | I26: Not Received | J26: Not Received | K26: Not Received | L26: Not Received
D27: Operating System (OS) | E27: Not Received | F27: Not Received | G27: Not Received | H27: Not Received | I27: Not Received | J27: Not Received | K27: Not Received | L27: Not Received
D28: Windows Active Directory (AD) | E28: Not Received
B29: B5 | C29: ="HR Resignation Listing for all in-scope entities from "&TEXT('A. Organizational Information'!C3,"dd-MMM-yyyy")&" to "&TEXT('A. Organizational Information'!C4,"dd-MMM-yyyy")&"" -> HR Resignation Listing for all in-scope entities from 01-Jan-2025 to 31-Dec-2025 | D29: Application (APP) | E29: Not Received | F29: Not Received | G29: Not Received | H29: Not Received | I29: Not Received | J29: Not Received | K29: Not Received | L29: Not Received
C30: Relevant data elements (RDE) within listing should include but not limited to the following: - Employee ID - Employee name - Resignation date | D30: Database (DB) | E30: Not Received | F30: Not Received | G30: Not Received | H30: Not Received | I30: Not Received | J30: Not Received | K30: Not Received | L30: Not Received
D31: Operating System (OS) | E31: Not Received | F31: Not Received | G31: Not Received | H31: Not Received | I31: Not Received | J31: Not Received | K31: Not Received | L31: Not Received
D32: Windows Active Directory (AD) | E32: Not Received
B33: B5a | C33: System screenshots of extraction step of the user listing extracted for B5. Please ensure the below are included in the screenshot: 1) Timestamp 2) Total number of row counts (to match with the total number of users shown in the user listing) | D33: Application (APP) | E33: Not Received | F33: Not Received | G33: Not Received | H33: Not Received | I33: Not Received | J33: Not Received | K33: Not Received | L33: Not Received
D34: Database (DB) | E34: Not Received | F34: Not Received | G34: Not Received | H34: Not Received | I34: Not Received | J34: Not Received | K34: Not Received | L34: Not Received
D35: Operating System (OS) | E35: Not Received | F35: Not Received | G35: Not Received | H35: Not Received | I35: Not Received | J35: Not Received | K35: Not Received | L35: Not Received
D36: Windows Active Directory (AD) | E36: Not Received
B37: B6 | C37: Full active user listing of all in-scope applications. Relevant data elements (RDE) within listing should include but not limited to the following: - User ID - User name - User access roles - User group | D37: Application (APP) | E37: Not Received | F37: Not Received | G37: Not Received | H37: Not Received | I37: Not Received | J37: Not Received | K37: Not Received | L37: Not Received
D38: Database (DB) | E38: Not Received | F38: Not Received | G38: Not Received | H38: Not Received | I38: Not Received | J38: Not Received | K38: Not Received | L38: Not Received
D39: Operating System (OS) | E39: Not Received | F39: Not Received | G39: Not Received | H39: Not Received | I39: Not Received | J39: Not Received | K39: Not Received | L39: Not Received
D40: Windows Active Directory (AD) | E40: Not Received
B41: B6a | C41: System screenshots of extraction step of the user listing extracted for B6. Please ensure the below are included in the screenshot: 1) Timestamp 2) Total number of row counts (to match with the total number of users shown in the user listing) | D41: Application (APP) | E41: Not Received | F41: Not Received | G41: Not Received | H41: Not Received | I41: Not Received | J41: Not Received | K41: Not Received | L41: Not Received
...

Sheet C. Program Changes
A1: CLIENT NAME: | C1: ='A. Organizational Information'!C1 -> Nagaworld Limited | N1: Item | O1: Percentage
A2: YEAR END: | C2: ='A. Organizational Information'!C2 -> FOR THE FINANCIAL YEAR ENDED 31-Dec-2025 | M2: All Received | N2: =COUNTIF($E$9:$H$18,M2) -> 0 | O2: =N2/SUM($N$2:$N$5) -> 0 | Q2: Not Applicable
M3: Partially Received | N3: =COUNTIF($E$9:$H$18,M3) -> 0 | O3: =N3/SUM($N$2:$N$5) -> 0 | Q3: Not Received
M4: Not Received | N4: =COUNTIF($E$9:$L$18,M4) -> 80 | O4: =N4/SUM($N$2:$N$5) -> 1 | Q4: Partially Received
M5: Not Applicable | N5: =COUNTIF($E$9:$H$18,M5) -> 0 | O5: =N5/SUM($N$2:$N$5) -> 0 | Q5: All Received
A7: List of Items Requested / Inquired | E7: Status | M7: Client's Remarks | N7: BDO Remarks
A8: Area | B8: File Ref | C8: Document / Evidence Requested | D8: Layers | E8: ='A. Organizational Information'!G1 -> Bally | F8: ='A. Organizational Information'!G2 -> Opera | G8: ='A. Organizational Information'!G3 -> Simphony POS | H8: ='A. Organizational Information'!G4 -> Material Control | I8: Sun Accounting | J8: HRMS | K8: K2 | L8: VR
A9: IT Program Change Approval & Testing | B9: C1 | C9: ="System generated list of program change logs for all in-scope systems from "&TEXT('A. Organizational Information'!C3,"dd-MMM-yyyy")&" to "&TEXT('A. Organizational Information'!C4,"dd-MMM-yyyy")&"" -> System generated list of program change logs for all in-scope systems from 01-Jan-2025 to 31-Dec-2025 | D9: Application (APP) | E9: Not Received | F9: Not Received | G9: Not Received | H9: Not Received | I9: Not Received | J9: Not Received | K9: Not Received | L9: Not Received
C10: Note: If system generated list is not available, to consider below options if applicable Option A - Ticketing system list of program change requests' | D10: Database (DB) | E10: Not Received | F10: Not Received | G10: Not Received | H10: Not Received | I10: Not Received | J10: Not Received | K10: Not Received | L10: Not Received
B11: C1a | C11: Screenshot of extraction step of the user listing extracted for C1. Please ensure the below are included in the screenshot: 1) Timestamp 2) Total number of row counts (to be consistent with the user listing) | D11: Application (APP) | E11: Not Received | F11: Not Received | G11: Not Received | H11: Not Received | I11: Not Received | J11: Not Received | K11: Not Received | L11: Not Received
D12: Database (DB) | E12: Not Received | F12: Not Received | G12: Not Received | H12: Not Received | I12: Not Received | J12: Not Received | K12: Not Received | L12: Not Received
B13: C2 | C13: Evidence of samples of program changes for all in-scope systems which includes but not limited to: - Approvals obtained prior to development of program change - User acceptance testing (UAT) performed over approved changes with sign offs by tester - Approvals obtained prior to deployment of program change - Post implaementation review of the approved changes made Note: Sample will only be selected when C1 is received. | D13: Application (APP) | E13: Not Received | F13: Not Received | G13: Not Received | H13: Not Received | I13: Not Received | J13: Not Received | K13: Not Received | L13: Not Received
D14: Database (DB) | E14: Not Received | F14: Not Received | G14: Not Received | H14: Not Received | I14: Not Received | J14: Not Received | K14: Not Received | L14: Not Received
A15: Migration of changes | B15: C3 | C15: List of users with access to migrate / perform changes for all in-scope systems | D15: Application (APP) | E15: Not Received | F15: Not Received | G15: Not Received | H15: Not Received | I15: Not Received | J15: Not Received | K15: Not Received | L15: Not Received
D16: Database (DB) | E16: Not Received | F16: Not Received | G16: Not Received | H16: Not Received | I16: Not Received | J16: Not Received | K16: Not Received | L16: Not Received
B17: C3a | C17: Screenshot of extraction step of the user listing extracted for C4. Please ensure the below are included in the screenshot: 1) Timestamp 2) Total number of row counts (to be consistent with the user listing) | D17: Application (APP) | E17: Not Received | F17: Not Received | G17: Not Received | H17: Not Received | I17: Not Received | J17: Not Received | K17: Not Received | L17: Not Received
D18: Database (DB) | E18: Not Received | F18: Not Received | G18: Not Received | H18: Not Received | I18: Not Received | J18: Not Received | K18: Not Received | L18: Not Received

Sheet D. Program Development
A1: CLIENT NAME: | C1: ='A. Organizational Information'!C1 -> Nagaworld Limited | F1: Item | G1: Percentage
A2: YEAR END: | C2: ='A. Organizational Information'!C2 -> FOR THE FINANCIAL YEAR ENDED 31-Dec-2025 | E2: All Received | F2: =COUNTIF($E$9:$E$14,E2) -> 0 | G2: =F2/SUM($F$2:$F$5) -> 0 | J2: Not Applicable
E3: Partially Received | F3: =COUNTIF($E$9:$E$14,E3) -> 0 | G3: =F3/SUM($F$2:$F$5) -> 0 | J3: Not Received
E4: Not Received | F4: =COUNTIF($E$9:$E$14,E4) -> 2 | G4: =F4/SUM($F$2:$F$5) -> 1 | J4: Partially Received
E5: Not Applicable | F5: =COUNTIF($E$9:$E$14,E5) -> 0 | G5: =F5/SUM($F$2:$F$5) -> 0 | J5: All Received
A7: List of Items Requested / Inquired | E7: Status | F7: Client's Remarks | G7: BDO Remarks
A8: Area | B8: File Ref | C8: Document / Evidence Requested | D8: Layers | E8: LNW (From Bally)
A9: Program Development Management / Product Acquisition | B9: D1 | C9: List of system / program development conducted for audit review period that has impact to financial reporting which includes (but not limited to): • Business and IT approvals • Meeting minutes • Project Management Plan (sighted, received the signed agreement) • Functional / Design specifications (sighted, received the signed agreement) • System & User Acceptance Testings samples • Data Migration (sign-off of closing balance and opening balance) • End user training • Post implementation review • Cessation of a project | D9: Application (APP) | E9: Not Received
B10: D1a | C10: Screenshot of extraction step of the user listing extracted for D1. Please ensure the below are included in the screenshot: 1) Timestamp 2) Total number of row counts (to be consistent with the user listing) | D10: Application (APP) | E10: Not Received

Sheet E. Computer Operations
A1: CLIENT NAME: | C1: ='A. Organizational Information'!C1 -> Nagaworld Limited | N1: Item | O1: Percentage
A2: YEAR END: | C2: ='A. Organizational Information'!C2 -> FOR THE FINANCIAL YEAR ENDED 31-Dec-2025 | M2: All Received | N2: =COUNTIF($E$9:$H$23,M2) -> 0 | O2: =N2/SUM($N$2:$N$5) -> 0 | Q2: Not Applicable
M3: Partially Received | N3: =COUNTIF($E$9:$H$23,M3) -> 0 | O3: =N3/SUM($N$2:$N$5) -> 0 | Q3: Not Received
M4: Not Received | N4: =COUNTIF($E$9:$L$23,M4) -> 64 | O4: =N4/SUM($N$2:$N$5) -> 0.69565217 | Q4: Partially Received
M5: Not Applicable | N5: =COUNTIF($E$9:$H$23,M5) -> 28 | O5: =N5/SUM($N$2:$N$5) -> 0.30434783 | Q5: All Received
A7: List of Items Requested / Inquired | E7: Status | M7: Client's Remarks | N7: BDO Remarks
A8: Area | B8: File Ref | C8: Document / Evidence Requested | D8: Layers | E8: ='A. Organizational Information'!G1 -> Bally | F8: ='A. Organizational Information'!G2 -> Opera | G8: ='A. Organizational Information'!G3 -> Simphony POS | H8: ='A. Organizational Information'!G4 -> Material Control | I8: Sun Accounting | J8: HRMS | K8: K2 | L8: VR
A9: Job Processing (Note: This control is only applicable if there is system interface ITAC) | B9: E1 | C9: ="System generated list of automated job processing (e.g. batch, scheduled, system, interface jobs) for all in-scope application from "&TEXT('A. Organizational Information'!C3,"dd-MMM-yyyy")&" to "&TEXT('A. Organizational Information'!C4,"dd-MMM-yyyy")&"" -> System generated list of automated job processing (e.g. batch, scheduled, system, interface jobs) for all in-scope application from 01-Jan-2025 to 31-Dec-2025 | D9: Application (APP) | E9: Not Received | F9: Not Received | G9: Not Received | H9: Not Received | I9: Not Received | J9: Not Received | K9: Not Received | L9: Not Received
B10: E1a | C10: Screenshot of extraction step of the listing extracted for E1. Please ensure the below are included in the screenshot: 1) Timestamp | D10: Application (APP) | E10: Not Received | F10: Not Received | G10: Not Received | H10: Not Received | I10: Not Received | J10: Not Received | K10: Not Received | L10: Not Received
B11: E2 | C11: Evidence of samples of job processing monitoring (e.g. audit logs, reviews, checklist, notification) conducted for all in-scope applications Note: Sample will only be selected when E1 is received. | D11: Application (APP) | E11: Not Received | F11: Not Received | G11: Not Received | H11: Not Received | I11: Not Received | J11: Not Received | K11: Not Received | L11: Not Received
B12: E3 | C12: Screenshot of email/notification raised for batch job status (in the event of errors) *Only applicable for automated job processing monitoring* | D12: Application (APP) | E12: Not Received | F12: Not Received | G12: Not Received | H12: Not Received | I12: Not Received | J12: Not Received | K12: Not Received | L12: Not Received
B13: E4 | C13: System generated list of users with access to modify batch jobs for all in-scope application | D13: Application (APP) | E13: Not Received | F13: Not Received | G13: Not Received | H13: Not Received | I13: Not Received | J13: Not Received | K13: Not Received | L13: Not Received
B14: E4a | C14: Screenshot of extraction step of the user listing extracted for E4. Please ensure the below are included in the screenshot: 1) Timestamp 2) Total number of row counts (to be consistent with the user listing) | D14: Application (APP) | E14: Not Received | F14: Not Received | G14: Not Received | H14: Not Received | I14: Not Received | J14: Not Received | K14: Not Received | L14: Not Received
A15: Backup Management (Note: This control is only applicable if there is issues with backup / cybersecurity attack during the financial year) | B15: E5 | C15: ="System generated list of backup schedules (e.g. batch, scheduled, system, interface jobs) for all in-scope application from "&TEXT('A. Organizational Information'!C3,"dd-MMM-yyyy")&" to "&TEXT('A. Organizational Information'!C4,"dd-MMM-yyyy")&"" -> System generated list of backup schedules (e.g. batch, scheduled, system, interface jobs) for all in-scope application from 01-Jan-2025 to 31-Dec-2025 | D15: Application (APP) | E15: Not Applicable | F15: Not Applicable | G15: Not Applicable | H15: Not Applicable | I15: Not Applicable | J15: Not Applicable | K15: Not Applicable | L15: Not Applicable
B16: E5a | C16: Screenshot of extraction step of the listing extracted for E5. Please ensure the below are included in the screenshot: 1) Timestamp | D16: Application (APP) | E16: Not Applicable | F16: Not Applicable | G16: Not Applicable | H16: Not Applicable | I16: Not Applicable | J16: Not Applicable | K16: Not Applicable | L16: Not Applicable
B17: E6 | C17: Evidence of samples of backup monitoring (e.g. audit logs, reviews, checklist, notification) conducted for all in-scope applications Note: Sample will only be selected when E5 is received. | D17: Application (APP) | E17: Not Applicable | F17: Not Applicable | G17: Not Applicable | H17: Not Applicable | I17: Not Applicable | J17: Not Applicable | K17: Not Applicable | L17: Not Applicable
B18: E7 | C18: Screenshot of email/notification raised for backup status (in the event of errors) *Only applicable for automated job processing monitoring* | D18: Application (APP) | E18: Not Applicable | F18: Not Applicable | G18: Not Applicable | H18: Not Applicable | I18: Not Applicable | J18: Not Applicable | K18: Not Applicable | L18: Not Applicable
B19: E8 | C19: ="Backup restoration testing performed for all in-scope applications from "&TEXT('A. Organizational Information'!C3,"dd-MMM-yyyy")&" to "&TEXT('A. Organizational Information'!C4,"dd-MMM-yyyy")&"." -> Backup restoration testing performed for all in-scope applications from 01-Jan-2025 to 31-Dec-2025. | D19: Application (APP) | E19: Not Applicable | F19: Not Applicable | G19: Not Applicable | H19: Not Applicable | I19: Not Applicable | J19: Not Applicable | K19: Not Applicable | L19: Not Applicable
B20: E9 | C20: System list of users with access to modify backup schedules for all in-scope application | D20: Application (APP) | E20: Not Applicable | F20: Not Applicable | G20: Not Applicable | H20: Not Applicable | I20: Not Applicable | J20: Not Applicable | K20: Not Applicable | L20: Not Applicable
B21: E9a | C21: Screenshot of extraction step of the user listing extracted for E9. Please ensure the below are included in the screenshot: 1) Timestamp 2) Total number of row counts (to be consistent with the user listing) | D21: Application (APP) | E21: Not Applicable | F21: Not Applicable | G21: Not Applicable | H21: Not Applicable | I21: Not Applicable | J21: Not Applicable | K21: Not Applicable | L21: Not Applicable
A22: Incident & Problem Management | B22: E10 | C22: ="System generated list of problem logs and incident reports (including operational failures) for all in-scope application from "&TEXT('A. Organizational Information'!C3,"dd-MMM-yyyy")&" to "&TEXT('A. Organizational Information'!C4,"dd-MMM-yyyy")&" which includes but not limited to the following:. - Request date - Closed date - Request status - Priority - Severity" -> System generated list of problem logs and incident reports (including operational failures) for all in-scope application from 01-Jan-2025 to 31-Dec-2025 which includes but not limited to the following:. - Request date - Closed date - Request status - Priority - Severity | D22: Application (APP) | E22: Not Received | F22: Not Received | G22: Not Received | H22: Not Received | I22: Not Received | J22: Not Received | K22: Not Received | L22: Not Received
B23: E10a | C23: Screenshot of extraction step of the report log extracted for E10. Please ensure the below are included in the screenshot: 1) Timestamp | D23: Application (APP) | E23: Not Received | F23: Not Received | G23: Not Received | H23: Not Received | I23: Not Received | J23: Not Received | K23: Not Received | L23: Not Received
B24: E11 | C24: Evidence of samples of resolution of incident tickets for all in-scope applications Note: Samples will only be selected when E11 is received. | D24: Application (APP) | E24: Not Received | F24: Not Received | G24: Not Received | H24: Not Received | I24: Not Received | J24: Not Received | K24: Not Received | L24: Not Received
B25: E12 | C25: Formalized Service Level Agreement (SLA) for each category of severity / priority of incidents | D25: Application (APP) | E25: Not Received | F25: Not Received | G25: Not Received | H25: Not Received | I25: Not Received | J25: Not Received | K25: Not Received | L25: Not Received
